<Testcase><Note>
********************* Keyword: connect *********************
</Note><Keyword><Name>connect</Name><Driver>cli_driver</Driver><Note>step number: 3</Note><Note>Teststep Description: connect</Note><Note>[2017-08-01 14:27:10] Keyword execution starts</Note><Arguments><argument name="system_name" value="fwcds-hd12_multi_subsys[cli_m2]" /><argument name="int_timeout" value="50" /></Arguments><Resultfile>/home/khusain/WAR-210/warriorframework/warrior/Warriorspace/Execution/pj_cli_full_17-08-01_14-26-42-393399/connect/connect_call_connect_telnet_multi_subsys/Results/Keyword_Results/step-3_connect.xml</Resultfile><Note>unexpected error: Traceback (most recent call last):
  File "/home/khusain/WAR-210/warriorframework/warrior/WarriorCore/step_driver.py", line 280, in main
    data_repository, system_name, parallel, queue)
  File "/home/khusain/WAR-210/warriorframework/warrior/WarriorCore/step_driver.py", line 163, in execute_step
    data_repository, args_repository)
  File "/home/khusain/WAR-210/warriorframework/warrior/WarriorCore/step_driver.py", line 72, in send_keyword_to_productdriver
    return driver_call.main(keyword, data_repository, args_repository)
  File "/home/khusain/WAR-210/warriorframework/warrior/ProductDrivers/cli_driver.py", line 27, in main
    return kw_driver.execute_keyword(keyword, data_repository, args_repository, package_list)
  File "/home/khusain/WAR-210/warriorframework/warrior/WarriorCore/kw_driver.py", line 50, in execute_keyword
    wdesc = Utils.testcase_Utils.get_wdesc_string(method_call)
  File "/home/khusain/WAR-210/warriorframework/warrior/Framework/Utils/testcase_Utils.py", line 154, in get_wdesc_string
    return TCOBJ.get_wdesc_string(function_object)
  File "/home/khusain/WAR-210/warriorframework/warrior/WarriorCore/Classes/testcase_utils_class.py", line 322, in get_wdesc_string
    source = inspect.getsource(function_object)
  File "/usr/lib/python2.7/inspect.py", line 700, in getsource
    lines, lnum = getsourcelines(object)
  File "/usr/lib/python2.7/inspect.py", line 689, in getsourcelines
    lines, lnum = findsource(object)
  File "/usr/lib/python2.7/inspect.py", line 528, in findsource
    raise IOError('source code not available')
IOError: source code not available
</Note><Note>failure action= next</Note></Keyword></Testcase>